Workbook

Sheet Informe de calificación_2206202
B1: Informe de calificación: CICLO INICIAL KARATE MADRID KA06 (14 alumnos)
D3: MED - C101 BASES DEL COMPORTAMIENTO DEPORTIVO | AH3: MED - C102 PRIMEROS AUXILIOS | BT3: MED -C103 ACTIVIDAD FÍSICA ADAPTADA Y DISCAPACIDAD | CL3: MED - C104 ORGANIZACIÓN DEPORTIVA
D4: TEMA 1. EL DEPORTE, ESCUELA DE VALORES (12%) | G4: TEMA 2. EL TÉCNICO DEPORTIVO COMO LIDER TRANSMISOR DE VALORES (13%) | J4: TEMA 6. UN PASEO POR LA INFANCIA (15%) | O4: TEMA 7. PRÁCTICAS DEPORTIVAS AJUSTADAS A LA INFANCIA (15%) | T4: TEMA 14. MOTIVACIÓN ADAPTADA A JÓVENES DEPORTISTAS (20%) | Y4: TEMA 16. TRABAJANDO CON GRUPOS (25%) | AB4: Total Evaluación Continua Ord. (70%) | AC4: Total Evaluación Continua Extr. (70%) | AD4: Examen presencial Conv.Ordinaria (30%) | AE4: Examen presencial Conv.Extr. (30%) | AF4: Nota total Módulo | AG4: Convalidado | AH4: TEMA 8. SITUACIONES DE URGENCIA EN EL DEPORTE (10%) | AK4: TEMA 9. PRESERVAR LA VIDA (35%) | AT4: TEMA 10. ATENCIÓN AL DEPORTISTA LESIONADO I (25%) | BA4: TEMA 11. ATENCIÓN AL DEPORTISTA LESIONADO II (20%) | BF4: TEMA 12. MANTENER LA CALMA (5%) | BI4: TEMA 13. ACTUAR IN SITU (5%) | BN4: Total Evaluación Continua Ord. (70%) | BO4: Total Evaluación Continua Extr (70%) | BP4: Examen presencial Conv.Ordinaria (30%) | BQ4: Examen presencial Conv.Extr. (30%) | BR4: Nota total Módulo | BS4: Convalidado | BT4: TEMA 5. LAS PERSONAS EN SITUACIÓN DE DISCAPACIDAD (60%) | CA4: TEMA 15. LA COMUNICACIÓN EN LA PRÁCTICA INCLUSIVA (40%) | CF4: Total Evaluación Continua Ord. (70%) | CG4: Total Evaluación Continua Extr (70%) | CH4: Examen presencial Conv.Ordinaria (30%) | CI4: Examen presencial Conv.Extr. (30%) | CJ4: Nota total Módulo | CK4: Convalidado | CL4: TEMA 3. ESTRUCTURA DEL DEPORTE ESPAÑOL (50%) | CQ4: TEMA 4. ORGANIZACIÓN DEPORTIVA AUTONÓMICA Y LOCAL (50%) | CT4: Total Evaluación Continua Ord. (70%) | CU4: Total Evaluación Continua Extr (70%) | CV4: Examen presencial Conv.Ordinaria (30%) | CW4: Examen presencia Conv.Extr. (30%) | CX4: Nota total Módulo | CY4: Convalidado
A5: Nº | B5: Nombre | C5: Apellidos | D5: Todo valores | F5: Total tema | G5: Líderes con valor | I5: Total tema | J5: ¿Qué sabes de la infancia? | L5: El Retrato Robot | N5: Total tema | O5: Desmontando a Richard | Q5: Iniciación deportiva respetuosa y segura | S5: Total tema | T5: Motivar sin palabras | V5: De Campeones a Mali | X5: Total tema | Y5: Tarea: Case Study Lealtad Rugby Club | AA5: Total tema | AH5: Análisis del entorno y conducta PAS | AJ5: Total tema | AK5: Foro-acertijo: "Staying alive" | AM5: Taller de RCP: Autoinstrucción | AO5: DESA | AQ5: Otras situaciones de riesgo vital | AS5: Total tema | AT5: Rescates y movilización | AV5: Atención al lesionado en el primer caso(40%) | AX5: ¿ Qué podrías hacer con estos deportistas?(30%) | AZ5: Total tema | BA5: Auténtica mala suerte: Noticias e imprevistos en triatlón(70%) | BC5: Otras lesiones menores(30%) | BE5: Total tema | BF5: Presta ayuda al choque de hockey | BH5: Total tema | BI5: Atiende in situ a estos deportistas | BK5: Atención in situ en el escenario de juego | BM5: Total tema | BT5: Y tú, ¿Cómo miras?(20%) | BV5: Me pongo en la piel(40%) | BX5: ¿Qué sabes sobre la discapacidad?(40%) | BZ5: Total tema | CA5: Entrenar a una persona con discapacidad(50%) | CC5: Cuestionario: Práctica deportiva en personas con discapacidad.(50%) | CE5: Total tema | CL5: Competencias de las instituciones | CN5: Quiz: Estructura del deporte nacional | CP5: Total tema | CQ5: Ayudas al deporte: requisitos y criterios de valoración. | CS5: Total tema
D6: T | E6: 1 | F6: =C6+E6 -> 1 | G6: T | H6: 1 | I6: =H6 -> 1 | J6: Q | K6: 0.3 | L6: T | M6: 0.7 | N6: =K6+M6 -> 1 | O6: T | P6: 0.9 | Q6: Q | R6: 0.1 | S6: =P6+R6 -> 1 | T6: T | U6: 0.1 | V6: T | W6: 0.9 | X6: =U6+W6 -> 1 | Y6: T | Z6: 1 | AA6: =Z6 -> 1 | AH6: T | AI6: 1 | AJ6: =AG6+AI6 -> 1 | AK6: F | AL6: 0.1 | AM6: T | AN6: 0.5 | AO6: T | AP6: 0.3 | AQ6: T | AR6: 0.1 | AS6: =AL6+AN6+AP6+AR6 -> 1 | AT6: T | AU6: 0.3 | AV6: T | AW6: 0.4 | AX6: T | AY6: 0.3 | AZ6: =AU6+AW6+AY6 -> 1 | BA6: T | BB6: 0.7 | BC6: T | BD6: 0.3 | BE6: =BB6+BD6 -> 1 | BF6: T | BG6: 1 | BH6: =BG6 -> 1 | BI6: T | BJ6: 0.6 | BK6: T | BL6: 0.4 | BM6: =BJ6+BL6 -> 1 | BT6: F | BU6: 0.2 | BV6: T | BW6: 0.4 | BX6: Q | BY6: 0.4 | BZ6: =BU6+BW6+BY6 -> 1 | CA6: T | CB6: 0.5 | CC6: T | CD6: 0.5 | CE6: =CB6+CD6 -> 1 | CL6: T | CM6: 0.7 | CN6: T | CO6: 0.3 | CP6: =CM6+CO6 -> 1 | CQ6: T | CR6: 1 | CS6: =CR6 -> 1
A7: 1 | B7: Marco Antonio | C7: Bedoya López | D7: - | F7: - | G7: - | I7: - | J7: - | L7: - | N7: - | O7: - | Q7: - | S7: - | T7: - | V7: - | X7: - | Y7: - | AA7: - | AB7: 0 | AC7: - | AD7: - | AE7: - | AF7: 0 | AG7: CV | AH7: - | AJ7: - | AK7: - | AM7: - | AO7: - | AQ7: - | AS7: - | AT7: - | AV7: - | AX7: - | AZ7: - | BA7: - | BC7: - | BE7: - | BF7: - | BH7: - | BI7: - | BK7: - | BM7: - | BN7: 0 | BO7: - | BP7: - | BQ7: - | BR7: 0 | BS7: CV | BT7: - | BV7: - | BX7: - | BZ7: - | CA7: - | CC7: - | CE7: - | CF7: 0 | CG7: - | CH7: - | CI7: - | CJ7: 0 | CK7: CV | CL7: - | CN7: - | CP7: - | CQ7: - | CS7: - | CT7: 0 | CU7: - | CV7: - | CW7: - | CX7: 0 | CY7: CV
A8: 2 | B8: Marcos | C8: Cano Sánchez | D8: 10 | F8: 1,2 | G8: 9 | I8: 1,17 | J8: 2,7 | L8: 6,5 | N8: 1,38 | O8: 4 | Q8: 1 | S8: 0,75 | T8: 0,7 | V8: 9 | X8: 1,94 | Y8: 9,5 | AA8: 2,38 | AB8: 6,17 | AC8: - | AD8: 5 | AE8: - | AF8: 7,67 | AH8: 9,5 | AJ8: 0,95 | AK8: 1 | AM8: 3,75 | AO8: 3 | AQ8: 0,8 | AS8: 2,99 | AT8: 3 | AV8: 4 | AX8: 1,5 | AZ8: 2,13 | BA8: 7 | BC8: 2,67 | BE8: 1,93 | BF8: 9 | BH8: 0,45 | BI8: 6 | BK8: 2 | BM8: 0,4 | BN8: 6,2 | BO8: - | BP8: 7,5 | BQ8: - | BR8: 8,45 | BT8: 2 | BV8: 3,5 | BX8: 3,8 | BZ8: 5,58 | CA8: 5 | CC8: 4,67 | CE8: 3,87 | CF8: 6,62 | CG8: - | CH8: 7 | CI8: - | CJ8: 8,72 | CL8: 5 | CN8: 2,14 | CP8: 3,57 | CQ8: 9,75 | CS8: 4,88 | CT8: 5,92 | CU8: - | CV8: 8 | CW8: - | CX8: 8,32
A9: 3 | B9: RAUL | C9: CANO SANCHEZ | D9: 8,5 | F9: 1,02 | G9: 9 | I9: 1,17 | J9: 2,4 | L9: 6,5 | N9: 1,34 | O9: 4 | Q9: 0,8 | S9: 0,72 | T9: 0,9 | V9: 9 | X9: 1,98 | Y9: 10 | AA9: 2,5 | AB9: 6,11 | AC9: - | AD9: - | AE9: - | AF9: 6,11 | AH9: 10 | AJ9: 1 | AK9: 1 | AM9: 4 | AO9: 3 | AQ9: 0,8 | AS9: 3,08 | AT9: 3 | AV9: 4 | AX9: 2 | AZ9: 2,25 | BA9: 7 | BC9: 2 | BE9: 1,8 | BF9: 9,5 | BH9: 0,48 | BI9: 6 | BK9: 1,2 | BM9: 0,36 | BN9: 6,28 | BO9: - | BP9: - | BQ9: - | BR9: 6,28 | BT9: 2 | BV9: 4 | BX9: 3,8 | BZ9: 5,88 | CA9: 5 | CC9: 5 | CE9: 4 | CF9: 6,92 | CG9: - | CH9: - | CI9: - | CJ9: 6,92 | CL9: 6 | CN9: 1,93 | CP9: 3,97 | CQ9: 3 | CS9: 1,5 | CT9: 3,83 | CU9: - | CV9: - | CW9: - | CX9: 3,83
A10: 4 | B10: DAVIS | C10: CASTILLO SALAZAR | D10: 7,5 | F10: 0,9 | G10: 6,5 | I10: 0,85 | J10: 2,1 | L10: 5,5 | N10: 1,14 | O10: 5,5 | Q10: 0,6 | S10: 0,92 | T10: 0,9 | V10: 9 | X10: 1,98 | Y10: 8 | AA10: 2 | AB10: 5,45 | AC10: - | AD10: 7,5 | AE10: - | AF10: 7,7 | AH10: 7 | AJ10: 0,7 | AK10: 1 | AM10: 3,5 | AO10: 3 | AQ10: 0,6 | AS10: 2,84 | AT10: 2 | AV10: 1,5 | AX10: 0,75 | AZ10: 1,06 | BA10: 6,25 | BC10: 0 | BE10: 1,25 | BF10: 6,5 | BH10: 0,33 | BI10: 5,5 | BK10: 0,4 | BM10: 0,3 | BN10: 4,54 | BO10: - | BP10: 8 | BQ10: - | BR10: 6,94 | BT10: 2 | BV10: 4 | BX10: 1,8 | BZ10: 4,68 | CA10: 5 | CC10: 3,17 | CE10: 3,27 | CF10: 5,57 | CG10: - | CH10: 8 | CI10: - | CJ10: 7,97 | CL10: 3 | CN10: 2,14 | CP10: 2,57 | CQ10: 4,5 | CS10: 2,25 | CT10: 3,37 | CU10: - | CV10: 6,5 | CW10: - | CX10: 5,32
A11: 5 | B11: RAMON | C11: CEBALLOS LOSA | D11: 10 | F11: 1,2 | G11: 8,5 | I11: 1,11 | J11: 3 | L11: 7 | N11: 1,5 | O11: 3 | Q11: 0,9 | S11: 0,59 | T11: 0,8 | V11: 9 | X11: 1,96 | Y11: 9,5 | AA11: 2,38 | AB11: 6,12 | AC11: - | AD11: 8,5 | AE11: - | AF11: 8,67 | AH11: 10 | AJ11: 1 | AK11: 1 | AM11: 4,75 | AO11: 3 | AQ11: 0,9 | AS11: 3,38 | AT11: 3 | AV11: 4 | AX11: 2,5 | AZ11: 2,38 | BA11: 7 | BC11: 2,33 | BE11: 1,87 | BF11: 8 | BH11: 0,4 | BI11: 5,25 | BK11: 2,4 | BM11: 0,38 | BN11: 6,59 | BO11: - | BP11: 10 | BQ11: - | BR11: 9,59 | BT11: 2 | BV11: 4 | BX11: 4 | BZ11: 6 | CA11: 5 | CC11: 5 | CE11: 4 | CF11: 7 | CG11: - | CH11: 10 | CI11: - | CJ11: 10 | CL11: 6 | CN11: 2,79 | CP11: 4,4 | CQ11: 5 | CS11: 2,5 | CT11: 4,83 | CU11: - | CV11: 10 | CW11: - | CX11: 7,83
A12: 6 | B12: SALOMÉ | C12: CRUZ TRUJILLO | D12: 10 | F12: 1,2 | G12: 7,5 | I12: 0,98 | J12: 2,7 | L12: 6,5 | N12: 1,38 | O12: 8 | Q12: 1 | S12: 1,35 | T12: 1 | V12: 9 | X12: 2 | Y12: 10 | AA12: 2,5 | AB12: 6,59 | AC12: - | AD12: 10 | AE12: - | AF12: 9,59 | AH12: 10 | AJ12: 1 | AK12: 1 | AM12: 3,25 | AO12: 2,4 | AQ12: 0,9 | AS12: 2,64 | AT12: 3 | AV12: 3,85 | AX12: 2,5 | AZ12: 2,34 | BA12: 7 | BC12: 2,67 | BE12: 1,93 | BF12: 6 | BH12: 0,3 | BI12: 6 | BK12: 2,8 | BM12: 0,44 | BN12: 6,06 | BO12: - | BP12: 10 | BQ12: - | BR12: 9,06 | BT12: 2 | BV12: 4 | BX12: 4 | BZ12: 6 | CA12: 4,25 | CC12: 5 | CE12: 3,7 | CF12: 6,79 | CG12: - | CH12: 10 | CI12: - | CJ12: 9,79 | CL12: 7 | CN12: 3 | CP12: 5 | CQ12: 8,25 | CS12: 4,13 | CT12: 6,39 | CU12: - | CV12: 10 | CW12: - | CX12: 9,39
A13: 7 | B13: Alejandro | C13: De Lera Saenz De Miera | D13: 10 | F13: 1,2 | G13: 7,5 | I13: 0,98 | J13: 2,7 | L13: 5,5 | N13: 1,23 | O13: 6 | Q13: 0,7 | S13: 1,01 | T13: 0,7 | V13: 8 | X13: 1,74 | Y13: 10 | AA13: 2,5 | AB13: 6,06 | AC13: - | AD13: 8,5 | AE13: - | AF13: 8,61 | AH13: 7,5 | AJ13: 0,75 | AK13: 1 | AM13: 4,25 | AO13: 3 | AQ13: 0,8 | AS13: 3,17 | AT13: 2 | AV13: 2 | AX13: 2,25 | AZ13: 1,56 | BA13: 7 | BC13: 2 | BE13: 1,8 | BF13: 7 | BH13: 0,35 | BI13: 6 | BK13: 1,2 | BM13: 0,36 | BN13: 5,59 | BO13: - | BP13: 8 | BQ13: - | BR13: 7,99 | BT13: 2 | BV13: 2,75 | BX13: 3,8 | BZ13: 5,13 | CA13: 5 | CC13: 4,5 | CE13: 3,8 | CF13: 6,25 | CG13: - | CH13: 7 | CI13: - | CJ13: 8,35 | CL13: 4 | CN13: 2,57 | CP13: 3,29 | CQ13: 7,25 | CS13: 3,63 | CT13: 4,84 | CU13: - | CV13: 8 | CW13: - | CX13: 7,24
A14: 8 | B14: JESUS | C14: FERNANDEZ FERNANDEZ | D14: 8,5 | F14: 1,02 | G14: 6 | I14: 0,78 | J14: 2,1 | L14: 4,5 | N14: 0,99 | O14: 5,5 | Q14: 0,7 | S14: 0,93 | T14: 0,8 | V14: 9 | X14: 1,96 | Y14: 9,5 | AA14: 2,38 | AB14: 5,64 | AC14: - | AD14: 8 | AE14: - | AF14: 8,04 | AH14: 8 | AJ14: 0,8 | AK14: 0 | AM14: 3,5 | AO14: 3 | AQ14: 0,8 | AS14: 2,56 | AT14: 1 | AV14: 2,25 | AX14: 2,25 | AZ14: 1,38 | BA14: 3,5 | BC14: 1,33 | BE14: 0,97 | BF14: 8 | BH14: 0,4 | BI14: 5 | BK14: 1,6 | BM14: 0,33 | BN14: 4,51 | BO14: - | BP14: 7 | BQ14: - | BR14: 6,61 | BT14: 2 | BV14: 4 | BX14: 3,4 | BZ14: 5,64 | CA14: 5 | CC14: 4,33 | CE14: 3,73 | CF14: 6,56 | CG14: - | CH14: 9,5 | CI14: - | CJ14: 9,41 | CL14: 5 | CN14: 2,14 | CP14: 3,57 | CQ14: 1,75 | CS14: 0,88 | CT14: 3,12 | CU14: - | CV14: 6 | CW14: - | CX14: 4,92
A15: 9 | B15: Lucía | C15: Guerrero Mouriz | D15: 10 | F15: 1,2 | G15: 9,5 | I15: 1,24 | J15: 2,1 | L15: 7 | N15: 1,37 | O15: 8 | Q15: 0,9 | S15: 1,34 | T15: 0,8 | V15: 9 | X15: 1,96 | Y15: 10 | AA15: 2,5 | AB15: 6,73 | AC15: - | AD15: 8 | AE15: - | AF15: 9,13 | AH15: 8,5 | AJ15: 0,85 | AK15: 1 | AM15: 1,25 | AO15: 1,7 | AQ15: 1 | AS15: 1,73 | AT15: 3 | AV15: 4 | AX15: 1,75 | AZ15: 2,19 | BA15: 7 | BC15: 2,67 | BE15: 1,93 | BF15: 8,5 | BH15: 0,43 | BI15: 6 | BK15: 2,4 | BM15: 0,42 | BN15: 5,29 | BO15: - | BP15: 9 | BQ15: - | BR15: 7,99 | BT15: 2 | BV15: 2,25 | BX15: 3,6 | BZ15: 4,71 | CA15: 4,25 | CC15: 4,83 | CE15: 3,63 | CF15: 5,84 | CG15: - | CH15: 10 | CI15: - | CJ15: 8,84 | CL15: 6 | CN15: 2,79 | CP15: 4,4 | CQ15: 10 | CS15: 5 | CT15: 6,58 | CU15: - | CV15: 7 | CW15: - | CX15: 8,68
A16: 10 | B16: Roque | C16: Mazoy Cortiñas | D16: 9 | F16: 1,08 | G16: 6 | I16: 0,78 | J16: 2,7 | L16: 6,5 | N16: 1,38 | O16: 9 | Q16: 0,6 | S16: 1,44 | T16: 0,7 | V16: 9 | X16: 1,94 | Y16: 10 | AA16: 2,5 | AB16: 6,38 | AC16: - | AD16: 7 | AE16: - | AF16: 8,48 | AH16: 10 | AJ16: 1 | AK16: 1 | AM16: 2,5 | AO16: 0,2 | AQ16: 0,7 | AS16: 1,54 | AT16: 2 | AV16: 4 | AX16: 1,5 | AZ16: 1,88 | BA16: 7 | BC16: 1,67 | BE16: 1,73 | BF16: 9,5 | BH16: 0,48 | BI16: 5,5 | BK16: 1,2 | BM16: 0,34 | BN16: 4,88 | BO16: - | BP16: 4 | BQ16: - | BR16: 6,08 | BT16: 1 | BV16: 3,5 | BX16: 3,6 | BZ16: 4,86 | CA16: 4,25 | CC16: 5 | CE16: 3,7 | CF16: 5,99 | CG16: - | CH16: 7,5 | CI16: - | CJ16: 8,24 | CL16: 4 | CN16: 2,57 | CP16: 3,29 | CQ16: 3,75 | CS16: 1,88 | CT16: 3,62 | CU16: - | CV16: 6 | CW16: - | CX16: 5,42
A17: 11 | B17: GUILLERMO | C17: MORENO MATA | D17: 10 | F17: 1,2 | G17: 4 | I17: 0,52 | J17: 2,4 | L17: 7 | N17: 1,41 | O17: 8,25 | Q17: 0,8 | S17: 1,36 | T17: 0,8 | V17: 9 | X17: 1,96 | Y17: 8,75 | AA17: 2,19 | AB17: 6,05 | AC17: - | AD17: 9 | AE17: - | AF17: 8,75 | AH17: 9,5 | AJ17: 0,95 | AK17: 1 | AM17: 4,25 | AO17: 3 | AQ17: 0,7 | AS17: 3,13 | AT17: 3 | AV17: 2,25 | AX17: 2,25 | AZ17: 1,88 | BA17: 7 | BC17: 2,33 | BE17: 1,87 | BF17: 6,5 | BH17: 0,33 | BI17: 6 | BK17: 2,4 | BM17: 0,42 | BN17: 6,01 | BO17: - | BP17: 9 | BQ17: - | BR17: 8,71 | BT17: 2 | BV17: 4 | BX17: 3,8 | BZ17: 5,88 | CA17: 5 | CC17: 4,33 | CE17: 3,73 | CF17: 6,73 | CG17: - | CH17: 9 | CI17: - | CJ17: 9,43 | CL17: 5 | CN17: 2,36 | CP17: 3,68 | CQ17: 6,75 | CS17: 3,38 | CT17: 4,94 | CU17: - | CV17: 8 | CW17: - | CX17: 7,34
A18: 12 | B18: LAURA | C18: PANIAGUA ARIAS | D18: 10 | F18: 1,2 | G18: 9,5 | I18: 1,24 | J18: 3 | L18: 6,5 | N18: 1,43 | O18: 7 | Q18: 1 | S18: 1,2 | T18: 1 | V18: 9 | X18: 2 | Y18: 9 | AA18: 2,25 | AB18: 6,52 | AC18: - | AD18: 10 | AE18: - | AF18: 9,52 | AH18: 10 | AJ18: 1 | AK18: 1 | AM18: 4,5 | AO18: 3 | AQ18: 1 | AS18: 3,33 | AT18: 3 | AV18: 4 | AX18: 1,75 | AZ18: 2,19 | BA18: 7 | BC18: 2,33 | BE18: 1,87 | BF18: 7,5 | BH18: 0,38 | BI18: 6 | BK18: 4 | BM18: 0,5 | BN18: 6,49 | BO18: - | BP18: 10 | BQ18: - | BR18: 9,49 | BT18: 2 | BV18: 4 | BX18: 3,8 | BZ18: 5,88 | CA18: 5 | CC18: 4,83 | CE18: 3,93 | CF18: 6,87 | CG18: - | CH18: 10 | CI18: - | CJ18: 9,87 | CL18: 6 | CN18: 2,57 | CP18: 4,29 | CQ18: 9,5 | CS18: 4,75 | CT18: 6,33 | CU18: - | CV18: 10 | CW18: - | CX18: 9,33
A19: 13 | B19: María del Rosario | C19: Quintáns Carballo | D19: 10 | F19: 1,2 | G19: 7 | I19: 0,91 | J19: 3 | L19: 7 | N19: 1,5 | O19: 9 | Q19: 1 | S19: 1,5 | T19: 0,9 | V19: 9 | X19: 1,98 | Y19: 10 | AA19: 2,5 | AB19: 6,71 | AC19: - | AD19: 10 | AE19: - | AF19: 9,71 | AH19: - | AJ19: - | AK19: - | AM19: - | AO19: - | AQ19: - | AS19: - | AT19: - | AV19: - | AX19: - | AZ19: - | BA19: - | BC19: - | BE19: - | BF19: - | BH19: - | BI19: - | BK19: - | BM19: - | BN19: 0 | BO19: - | BP19: - | BQ19: - | BR19: 0 | BS19: CV | BT19: 2 | BV19: 3,5 | BX19: 3,6 | BZ19: 5,46 | CA19: 5 | CC19: 4,83 | CE19: 3,93 | CF19: 6,57 | CG19: - | CH19: 10 | CI19: - | CJ19: 9,57 | CL19: 6 | CN19: 2,36 | CP19: 4,18 | CQ19: 8,75 | CS19: 4,38 | CT19: 5,99 | CU19: - | CV19: 10 | CW19: - | CX19: 8,99
A20: 14 | B20: ALAIN | C20: TALLON JIMENEZ | D20: 10 | F20: 1,2 | G20: 7,5 | I20: 0,98 | J20: 3 | L20: 7 | N20: 1,5 | O20: 9 | Q20: 0,9 | S20: 1,49 | T20: 0,9 | V20: 9 | X20: 1,98 | Y20: 10 | AA20: 2,5 | AB20: 6,76 | AC20: - | AD20: 10 | AE20: - | AF20: 9,76 | AH20: 9 | AJ20: 0,9 | AK20: 1 | AM20: 4,25 | AO20: 3 | AQ20: 1 | AS20: 3,24 | AT20: 2 | AV20: 4 | AX20: 2,25 | AZ20: 2,06 | BA20: 7 | BC20: 2,67 | BE20: 1,93 | BF20: 7,5 | BH20: 0,38 | BI20: 6 | BK20: 2,4 | BM20: 0,42 | BN20: 6,25 | BO20: - | BP20: 8 | BQ20: - | BR20: 8,65 | BT20: 2 | BV20: 2 | BX20: 3,8 | BZ20: 4,68 | CA20: 5 | CC20: 4 | CE20: 3,6 | CF20: 5,8 | CG20: - | CH20: 10 | CI20: - | CJ20: 8,8 | CL20: 5 | CN20: 2,57 | CP20: 3,79 | CQ20: 5,25 | CS20: 2,63 | CT20: 4,49 | CU20: - | CV20: 8,5 | CW20: - | CX20: 7,04
B25: LEYENDA COLORES | E25: LEYENDA DE LOS COLORES DE LAS CASILLAS
B27: AUTOMATICA (MOODLE) | F27: AUTOMÁTICA (MOODLE)
G29: - | J29: TAREA NO ENTREGADA
G31: 0 | J31: ACTIVIDAD CALIFICADA CON UN 0
G32: -
G33: 0 | J33: ACTIVIDAD CALIFICADA EN EL INFORME DE CALIFICACIÓN MANUALMENTE
F36: MANUAL EN EL EXCEL
J38: EXAMEN < 5
J40: NOTA FINAL DEL MÓDULO MODIFICADA MANUALMENTE

Sheet Informe de calificación_CIKA06
B1: Informe de calificación: CICLO INICIAL KARATE MADRID KA06 (14 alumnos)
D3: MED - C101 BASES DEL COMPORTAMIENTO DEPORTIVO | AH3: MED - C102 PRIMEROS AUXILIOS | BT3: MED -C103 ACTIVIDAD FÍSICA ADAPTADA Y DISCAPACIDAD | CL3: MED - C104 ORGANIZACIÓN DEPORTIVA
D4: TEMA 1. EL DEPORTE, ESCUELA DE VALORES (12%) | G4: TEMA 2. EL TÉCNICO DEPORTIVO COMO LIDER TRANSMISOR DE VALORES (13%) | J4: TEMA 6. UN PASEO POR LA INFANCIA (15%) | O4: TEMA 7. PRÁCTICAS DEPORTIVAS AJUSTADAS A LA INFANCIA (15%) | T4: TEMA 14. MOTIVACIÓN ADAPTADA A JÓVENES DEPORTISTAS (20%) | Y4: TEMA 16. TRABAJANDO CON GRUPOS (25%) | AB4: Total Evaluación Continua Ord. (70%) | AC4: Total Evaluación Continua Extr. (70%) | AD4: Examen presencial Conv.Ordinaria (30%) | AE4: Examen presencial Conv.Extr. (30%) | AF4: Nota total Módulo | AG4: Convalidado | AH4: TEMA 8. SITUACIONES DE URGENCIA EN EL DEPORTE (10%) | AK4: TEMA 9. PRESERVAR LA VIDA (35%) | AT4: TEMA 10. ATENCIÓN AL DEPORTISTA LESIONADO I (25%) | BA4: TEMA 11. ATENCIÓN AL DEPORTISTA LESIONADO II (20%) | BF4: TEMA 12. MANTENER LA CALMA (5%) | BI4: TEMA 13. ACTUAR IN SITU (5%) | BN4: Total Evaluación Continua Ord. (70%) | BO4: Total Evaluación Continua Extr (70%) | BP4: Examen presencial Conv.Ordinaria (30%) | BQ4: Examen presencial Conv.Extr. (30%) | BR4: Nota total Módulo | BS4: Convalidado | BT4: TEMA 5. LAS PERSONAS EN SITUACIÓN DE DISCAPACIDAD (60%) | CA4: TEMA 15. LA COMUNICACIÓN EN LA PRÁCTICA INCLUSIVA (40%) | CF4: Total Evaluación Continua Ord. (70%) | CG4: Total Evaluación Continua Extr (70%) | CH4: Examen presencial Conv.Ordinaria (30%) | CI4: Examen presencial Conv.Extr. (30%) | CJ4: Nota total Módulo | CK4: Convalidado | CL4: TEMA 3. ESTRUCTURA DEL DEPORTE ESPAÑOL (50%) | CQ4: TEMA 4. ORGANIZACIÓN DEPORTIVA AUTONÓMICA Y LOCAL (50%) | CT4: Total Evaluación Continua Ord. (70%) | CU4: Total Evaluación Continua Extr (70%) | CV4: Examen presencial Conv.Ordinaria (30%) | CW4: Examen presencia Conv.Extr. (30%) | CX4: Nota total Módulo | CY4: Convalidado
A5: Nº | B5: Nombre | C5: Apellidos | D5: Todo valores | F5: Total tema | G5: Líderes con valor | I5: Total tema | J5: ¿Qué sabes de la infancia? | L5: El Retrato Robot | N5: Total tema | O5: Desmontando a Richard | Q5: Iniciación deportiva respetuosa y segura | S5: Total tema | T5: Motivar sin palabras | V5: De Campeones a Mali | X5: Total tema | Y5: Tarea: Case Study Lealtad Rugby Club | AA5: Total tema | AH5: Análisis del entorno y conducta PAS | AJ5: Total tema | AK5: Foro-acertijo: "Staying alive" | AM5: Taller de RCP: Autoinstrucción | AO5: DESA | AQ5: Otras situaciones de riesgo vital | AS5: Total tema | AT5: Rescates y movilización | AV5: Atención al lesionado en el primer caso(40%) | AX5: ¿ Qué podrías hacer con estos deportistas?(30%) | AZ5: Total tema | BA5: Auténtica mala suerte: Noticias e imprevistos en triatlón(70%) | BC5: Otras lesiones menores(30%) | BE5: Total tema | BF5: Presta ayuda al choque de hockey | BH5: Total tema | BI5: Atiende in situ a estos deportistas | BK5: Atención in situ en el escenario de juego | BM5: Total tema | BT5: Y tú, ¿Cómo miras?(20%) | BV5: Me pongo en la piel(40%) | BX5: ¿Qué sabes sobre la discapacidad?(40%) | BZ5: Total tema | CA5: Entrenar a una persona con discapacidad(50%) | CC5: Cuestionario: Práctica deportiva en personas con discapacidad.(50%) | CE5: Total tema | CL5: Competencias de las instituciones | CN5: Quiz: Estructura del deporte nacional | CP5: Total tema | CQ5: Ayudas al deporte: requisitos y criterios de valoración. | CS5: Total tema
D6: T | E6: 1 | F6: =C6+E6 -> 1 | G6: T | H6: 1 | I6: =H6 -> 1 | J6: Q | K6: 0.3 | L6: T | M6: 0.7 | N6: =K6+M6 -> 1 | O6: T | P6: 0.9 | Q6: Q | R6: 0.1 | S6: =P6+R6 -> 1 | T6: T | U6: 0.1 | V6: T | W6: 0.9 | X6: =U6+W6 -> 1 | Y6: T | Z6: 1 | AA6: =Z6 -> 1 | AH6: T | AI6: 1 | AJ6: =AG6+AI6 -> 1 | AK6: F | AL6: 0.1 | AM6: T | AN6: 0.5 | AO6: T | AP6: 0.3 | AQ6: T | AR6: 0.1 | AS6: =AL6+AN6+AP6+AR6 -> 1 | AT6: T | AU6: 0.3 | AV6: T | AW6: 0.4 | AX6: T | AY6: 0.3 | AZ6: =AU6+AW6+AY6 -> 1 | BA6: T | BB6: 0.7 | BC6: T | BD6: 0.3 | BE6: =BB6+BD6 -> 1 | BF6: T | BG6: 1 | BH6: =BG6 -> 1 | BI6: T | BJ6: 0.6 | BK6: T | BL6: 0.4 | BM6: =BJ6+BL6 -> 1 | BT6: F | BU6: 0.2 | BV6: T | BW6: 0.4 | BX6: Q | BY6: 0.4 | BZ6: =BU6+BW6+BY6 -> 1 | CA6: T | CB6: 0.5 | CC6: T | CD6: 0.5 | CE6: =CB6+CD6 -> 1 | CL6: T | CM6: 0.7 | CN6: T | CO6: 0.3 | CP6: =CM6+CO6 -> 1 | CQ6: T | CR6: 1 | CS6: =CR6 -> 1
A7: 1 | B7: Marco Antonio | C7: Bedoya López | D7: ='Notas del Moodle'!C8 -> - | F7: ='Notas del Moodle'!D8 -> - | G7: ='Notas del Moodle'!E8 -> - | I7: ='Notas del Moodle'!F8 -> - | J7: ='Notas del Moodle'!G8 -> - | L7: ='Notas del Moodle'!H8 -> - | N7: ='Notas del Moodle'!I8 -> - | O7: ='Notas del Moodle'!J8 -> - | Q7: ='Notas del Moodle'!K8 -> - | S7: ='Notas del Moodle'!L8 -> - | T7: ='Notas del Moodle'!M8 -> - | V7: ='Notas del Moodle'!N8 -> - | X7: ='Notas del Moodle'!O9 -> 1,94 | Y7: ='Notas del Moodle'!P8 -> - | AA7: ='Notas del Moodle'!Q8 -> - | AB7: ='Notas del Moodle'!R8 -> 0 | AC7: ='Notas del Moodle'!S8 -> - | AD7: ='Notas del Moodle'!T8 -> - | AE7: ='Notas del Moodle'!U8 -> - | AF7: CV | AG7: ='Notas del Moodle'!W8 -> CV | AH7: ='Notas del Moodle'!X8 -> - | AJ7: ='Notas del Moodle'!Y8 -> - | AK7: ='Notas del Moodle'!Z8 -> - | AM7: ='Notas del Moodle'!AA8 -> - | AO7: ='Notas del Moodle'!AB8 -> - | AQ7: ='Notas del Moodle'!AC8 -> - | AS7: ='Notas del Moodle'!AD8 -> - | AT7: ='Notas del Moodle'!AE8 -> - | AV7: ='Notas del Moodle'!AF8 -> - | AX7: ='Notas del Moodle'!AG8 -> - | AZ7: ='Notas del Moodle'!AH8 -> - | BA7: ='Notas del Moodle'!AI8 -> - | BC7: ='Notas del Moodle'!AJ8 -> - | BE7: ='Notas del Moodle'!AK8 -> - | BF7: ='Notas del Moodle'!AL8 -> - | BH7: ='Notas del Moodle'!AM8 -> - | BI7: ='Notas del Moodle'!AN8 -> - | BK7: ='Notas del Moodle'!AO8 -> - | BM7: ='Notas del Moodle'!AP8 -> - | BN7: ='Notas del Moodle'!AQ8 -> 0 | BO7: ='Notas del Moodle'!AR8 -> - | BP7: ='Notas del Moodle'!AS8 -> - | BQ7: ='Notas del Moodle'!AT8 -> - | BR7: CV | BS7: ='Notas del Moodle'!AV8 -> CV | BT7: ='Notas del Moodle'!AW8 -> - | BV7: ='Notas del Moodle'!AX8 -> - | BX7: ='Notas del Moodle'!AY8 -> - | BZ7: ='Notas del Moodle'!AZ8 -> - | CA7: ='Notas del Moodle'!BA8 -> - | CC7: ='Notas del Moodle'!BB8 -> - | CE7: ='Notas del Moodle'!BC8 -> - | CF7: ='Notas del Moodle'!BD8 -> 0 | CG7: ='Notas del Moodle'!BE8 -> - | CH7: ='Notas del Moodle'!BF8 -> - | CI7: ='Notas del Moodle'!BG8 -> - | CJ7: CV | CK7: ='Notas del Moodle'!BI8 -> CV | CL7: ='Notas del Moodle'!BJ8 -> - | CN7: ='Notas del Moodle'!BK8 -> - | CP7: ='Notas del Moodle'!BL8 -> - | CQ7: ='Notas del Moodle'!BM8 -> - | CS7: ='Notas del Moodle'!BN8 -> - | CT7: ='Notas del Moodle'!BO8 -> 0 | CU7: ='Notas del Moodle'!BP8 -> - | CV7: ='Notas del Moodle'!BQ8 -> - | CW7: ='Notas del Moodle'!BR8 -> - | CX7: CV | CY7: ='Notas del Moodle'!BT8 -> CV
A8: 2 | B8: Marcos | C8: Cano Sánchez | D8: ='Notas del Moodle'!C9 -> 10 | F8: ='Notas del Moodle'!D9 -> 1,2 | G8: ='Notas del Moodle'!E9 -> 9 | I8: ='Notas del Moodle'!F9 -> 1,17 | J8: ='Notas del Moodle'!G9 -> 2,7 | L8: ='Notas del Moodle'!H9 -> 6,5 | N8: ='Notas del Moodle'!I9 -> 1,38 | O8: ='Notas del Moodle'!J9 -> 4 | Q8: ='Notas del Moodle'!K9 -> 1 | S8: ='Notas del Moodle'!L9 -> 0,75 | T8: ='Notas del Moodle'!M9 -> 0,7 | V8: ='Notas del Moodle'!N9 -> 9 | X8: ='Notas del Moodle'!O10 -> 1,98 | Y8: ='Notas del Moodle'!P9 -> 9,5 | AA8: ='Notas del Moodle'!Q9 -> 2,38 | AB8: ='Notas del Moodle'!R9 -> 6,17 | AC8: ='Notas del Moodle'!S9 -> - | AD8: ='Notas del Moodle'!T9 -> 5 | AE8: ='Notas del Moodle'!U9 -> - | AF8: ='Notas del Moodle'!V9 -> 7,67 | AH8: ='Notas del Moodle'!X9 -> 9,5 | AJ8: ='Notas del Moodle'!Y9 -> 0,95 | AK8: ='Notas del Moodle'!Z9 -> 1 | AM8: ='Notas del Moodle'!AA9 -> 3,75 | AO8: ='Notas del Moodle'!AB9 -> 3 | AQ8: ='Notas del Moodle'!AC9 -> 0,8 | AS8: ='Notas del Moodle'!AD9 -> 2,99 | AT8: ='Notas del Moodle'!AE9 -> 3 | AV8: ='Notas del Moodle'!AF9 -> 4 | AX8: ='Notas del Moodle'!AG9 -> 1,5 | AZ8: ='Notas del Moodle'!AH9 -> 2,13 | BA8: ='Notas del Moodle'!AI9 -> 7 | BC8: ='Notas del Moodle'!AJ9 -> 2,67 | BE8: ='Notas del Moodle'!AK9 -> 1,93 | BF8: ='Notas del Moodle'!AL9 -> 9 | BH8: ='Notas del Moodle'!AM9 -> 0,45 | BI8: ='Notas del Moodle'!AN9 -> 6 | BK8: ='Notas del Moodle'!AO9 -> 2 | BM8: ='Notas del Moodle'!AP9 -> 0,4 | BN8: ='Notas del Moodle'!AQ9 -> 6,2 | BO8: ='Notas del Moodle'!AR9 -> - | BP8: ='Notas del Moodle'!AS9 -> 7,5 | BQ8: ='Notas del Moodle'!AT9 -> - | BR8: ='Notas del Moodle'!AU9 -> 8,45 | BT8: ='Notas del Moodle'!AW9 -> 2 | BV8: ='Notas del Moodle'!AX9 -> 3,5 | BX8: ='Notas del Moodle'!AY9 -> 3,8 | BZ8: ='Notas del Moodle'!AZ9 -> 5,58 | CA8: ='Notas del Moodle'!BA9 -> 5 | CC8: ='Notas del Moodle'!BB9 -> 4,67 | CE8: ='Notas del Moodle'!BC9 -> 3,87 | CF8: ='Notas del Moodle'!BD9 -> 6,62 | CG8: ='Notas del Moodle'!BE9 -> - | CH8: ='Notas del Moodle'!BF9 -> 7 | CI8: ='Notas del Moodle'!BG9 -> - | CJ8: ='Notas del Moodle'!BH9 -> 8,72 | CL8: ='Notas del Moodle'!BJ9 -> 5 | CN8: ='Notas del Moodle'!BK9 -> 2,14 | CP8: ='Notas del Moodle'!BL9 -> 3,57 | CQ8: ='Notas del Moodle'!BM9 -> 9,75 | CS8: ='Notas del Moodle'!BN9 -> 4,88 | CT8: ='Notas del Moodle'!BO9 -> 5,92 | CU8: ='Notas del Moodle'!BP9 -> - | CV8: ='Notas del Moodle'!BQ9 -> 8 | CW8: - | CX8: ='Notas del Moodle'!BS9 -> 8,32
A9: 3 | B9: RAUL | C9: CANO SANCHEZ | D9: ='Notas del Moodle'!C10 -> 8,5 | F9: ='Notas del Moodle'!D10 -> 1,02 | G9: ='Notas del Moodle'!E10 -> 9 | I9: ='Notas del Moodle'!F10 -> 1,17 | J9: ='Notas del Moodle'!G10 -> 2,4 | L9: ='Notas del Moodle'!H10 -> 6,5 | N9: ='Notas del Moodle'!I10 -> 1,34 | O9: ='Notas del Moodle'!J10 -> 4 | Q9: ='Notas del Moodle'!K10 -> 0,8 | S9: ='Notas del Moodle'!L10 -> 0,72 | T9: ='Notas del Moodle'!M10 -> 0,9 | V9: ='Notas del Moodle'!N10 -> 9 | X9: ='Notas del Moodle'!O11 -> 1,98 | Y9: ='Notas del Moodle'!P10 -> 10 | AA9: ='Notas del Moodle'!Q10 -> 2,5 | AB9: ='Notas del Moodle'!R10 -> 6,11 | AC9: ='Notas del Moodle'!S10 -> - | AD9: ='Notas del Moodle'!T10 -> - | AE9: ='Notas del Moodle'!U10 -> - | AF9: ='Notas del Moodle'!V10 -> 6,11 | AH9: ='Notas del Moodle'!X10 -> 10 | AJ9: ='Notas del Moodle'!Y10 -> 1 | AK9: ='Notas del Moodle'!Z10 -> 1 | AM9: ='Notas del Moodle'!AA10 -> 4 | AO9: ='Notas del Moodle'!AB10 -> 3 | AQ9: ='Notas del Moodle'!AC10 -> 0,8 | AS9: ='Notas del Moodle'!AD10 -> 3,08 | AT9: ='Notas del Moodle'!AE10 -> 3 | AV9: ='Notas del Moodle'!AF10 -> 4 | AX9: ='Notas del Moodle'!AG10 -> 2 | AZ9: ='Notas del Moodle'!AH10 -> 2,25 | BA9: ='Notas del Moodle'!AI10 -> 7 | BC9: ='Notas del Moodle'!AJ10 -> 2 | BE9: ='Notas del Moodle'!AK10 -> 1,8 | BF9: ='Notas del Moodle'!AL10 -> 9,5 | BH9: ='Notas del Moodle'!AM10 -> 0,48 | BI9: ='Notas del Moodle'!AN10 -> 6 | BK9: ='Notas del Moodle'!AO10 -> 1,2 | BM9: ='Notas del Moodle'!AP10 -> 0,36 | BN9: ='Notas del Moodle'!AQ10 -> 6,28 | BO9: ='Notas del Moodle'!AR10 -> - | BP9: ='Notas del Moodle'!AS10 -> - | BQ9: ='Notas del Moodle'!AT10 -> - | BR9: ='Notas del Moodle'!AU10 -> 6,28 | BT9: ='Notas del Moodle'!AW10 -> 2 | BV9: ='Notas del Moodle'!AX10 -> 4 | BX9: ='Notas del Moodle'!AY10 -> 3,8 | BZ9: ='Notas del Moodle'!AZ10 -> 5,88 | CA9: ='Notas del Moodle'!BA10 -> 5 | CC9: ='Notas del Moodle'!BB10 -> 5 | CE9: ='Notas del Moodle'!BC10 -> 4 | CF9: ='Notas del Moodle'!BD10 -> 6,92 | CG9: ='Notas del Moodle'!BE10 -> - | CH9: ='Notas del Moodle'!BF10 -> - | CI9: ='Notas del Moodle'!BG10 -> - | CJ9: ='Notas del Moodle'!BH10 -> 6,92 | CL9: ='Notas del Moodle'!BJ10 -> 6 | CN9: ='Notas del Moodle'!BK10 -> 1,93 | CP9: ='Notas del Moodle'!BL10 -> 3,97 | CQ9: ='Notas del Moodle'!BM10 -> 3 | CS9: ='Notas del Moodle'!BN10 -> 1,5 | CT9: ='Notas del Moodle'!BO10 -> 3,83 | CU9: ='Notas del Moodle'!BP10 -> - | CV9: ='Notas del Moodle'!BQ10 -> - | CW9: - | CX9: ='Notas del Moodle'!BS10 -> 3,83
A10: 4 | B10: DAVIS | C10: CASTILLO SALAZAR | D10: ='Notas del Moodle'!C11 -> 7,5 | F10: ='Notas del Moodle'!D11 -> 0,9 | G10: ='Notas del Moodle'!E11 -> 6,5 | I10: ='Notas del Moodle'!F11 -> 0,85 | J10: ='Notas del Moodle'!G11 -> 2,1 | L10: ='Notas del Moodle'!H11 -> 5,5 | N10: ='Notas del Moodle'!I11 -> 1,14 | O10: ='Notas del Moodle'!J11 -> 5,5 | Q10: ='Notas del Moodle'!K11 -> 0,6 | S10: ='Notas del Moodle'!L11 -> 0,92 | T10: ='Notas del Moodle'!M11 -> 0,9 | V10: ='Notas del Moodle'!N11 -> 9 | X10: ='Notas del Moodle'!O12 -> 1,96 | Y10: ='Notas del Moodle'!P11 -> 8 | AA10: ='Notas del Moodle'!Q11 -> 2 | AB10: ='Notas del Moodle'!R11 -> 5,45 | AC10: ='Notas del Moodle'!S11 -> - | AD10: ='Notas del Moodle'!T11 -> 7,5 | AE10: ='Notas del Moodle'!U11 -> - | AF10: ='Notas del Moodle'!V11 -> 7,7 | AH10: ='Notas del Moodle'!X11 -> 7 | AJ10: ='Notas del Moodle'!Y11 -> 0,7 | AK10: ='Notas del Moodle'!Z11 -> 1 | AM10: ='Notas del Moodle'!AA11 -> 3,5 | AO10: ='Notas del Moodle'!AB11 -> 3 | AQ10: ='Notas del Moodle'!AC11 -> 0,6 | AS10: ='Notas del Moodle'!AD11 -> 2,84 | AT10: ='Notas del Moodle'!AE11 -> 2 | AV10: ='Notas del Moodle'!AF11 -> 1,5 | AX10: ='Notas del Moodle'!AG11 -> 0,75 | AZ10: ='Notas del Moodle'!AH11 -> 1,06 | BA10: ='Notas del Moodle'!AI11 -> 6,25 | BC10: ='Notas del Moodle'!AJ11 -> 0 | BE10: ='Notas del Moodle'!AK11 -> 1,25 | BF10: ='Notas del Moodle'!AL11 -> 6,5 | BH10: ='Notas del Moodle'!AM11 -> 0,33 | BI10: ='Notas del Moodle'!AN11 -> 5,5 | BK10: ='Notas del Moodle'!AO11 -> 0,4 | BM10: ='Notas del Moodle'!AP11 -> 0,3 | BN10: ='Notas del Moodle'!AQ11 -> 4,54 | BO10: ='Notas del Moodle'!AR11 -> - | BP10: ='Notas del Moodle'!AS11 -> 8 | BQ10: ='Notas del Moodle'!AT11 -> - | BR10: ='Notas del Moodle'!AU11 -> 6,94 | BT10: ='Notas del Moodle'!AW11 -> 2 | BV10: ='Notas del Moodle'!AX11 -> 4 | BX10: ='Notas del Moodle'!AY11 -> 1,8 | BZ10: ='Notas del Moodle'!AZ11 -> 4,68 | CA10: ='Notas del Moodle'!BA11 -> 5 | CC10: ='Notas del Moodle'!BB11 -> 3,17 | CE10: ='Notas del Moodle'!BC11 -> 3,27 | CF10: ='Notas del Moodle'!BD11 -> 5,57 | CG10: ='Notas del Moodle'!BE11 -> - | CH10: ='Notas del Moodle'!BF11 -> 8 | CI10: ='Notas del Moodle'!BG11 -> - | CJ10: ='Notas del Moodle'!BH11 -> 7,97 | CL10: ='Notas del Moodle'!BJ11 -> 3 | CN10: ='Notas del Moodle'!BK11 -> 2,14 | CP10: ='Notas del Moodle'!BL11 -> 2,57 | CQ10: ='Notas del Moodle'!BM11 -> 4,5 | CS10: ='Notas del Moodle'!BN11 -> 2,25 | CT10: ='Notas del Moodle'!BO11 -> 3,37 | CU10: ='Notas del Moodle'!BP11 -> - | CV10: ='Notas del Moodle'!BQ11 -> 6,5 | CW10: - | CX10: ='Notas del Moodle'!BS11 -> 5,32
A11: 5 | B11: RAMON | C11: CEBALLOS LOSA | D11: ='Notas del Moodle'!C12 -> 10 | F11: ='Notas del Moodle'!D12 -> 1,2 | G11: ='Notas del Moodle'!E12 -> 8,5 | I11: ='Notas del Moodle'!F12 -> 1,11 | J11: ='Notas del Moodle'!G12 -> 3 | L11: ='Notas del Moodle'!H12 -> 7 | N11: ='Notas del Moodle'!I12 -> 1,5 | O11: ='Notas del Moodle'!J12 -> 3 | Q11: ='Notas del Moodle'!K12 -> 0,9 | S11: ='Notas del Moodle'!L12 -> 0,59 | T11: ='Notas del Moodle'!M12 -> 0,8 | V11: ='Notas del Moodle'!N12 -> 9 | X11: ='Notas del Moodle'!O13 -> 2 | Y11: ='Notas del Moodle'!P12 -> 9,5 | AA11: ='Notas del Moodle'!Q12 -> 2,38 | AB11: ='Notas del Moodle'!R12 -> 6,12 | AC11: ='Notas del Moodle'!S12 -> - | AD11: ='Notas del Moodle'!T12 -> 8,5 | AE11: ='Notas del Moodle'!U12 -> - | AF11: ='Notas del Moodle'!V12 -> 8,67 | AH11: ='Notas del Moodle'!X12 -> 10 | AJ11: ='Notas del Moodle'!Y12 -> 1 | AK11: ='Notas del Moodle'!Z12 -> 1 | AM11: ='Notas del Moodle'!AA12 -> 4,75 | AO11: ='Notas del Moodle'!AB12 -> 3 | AQ11: ='Notas del Moodle'!AC12 -> 0,9 | AS11: ='Notas del Moodle'!AD12 -> 3,38 | AT11: ='Notas del Moodle'!AE12 -> 3 | AV11: ='Notas del Moodle'!AF12 -> 4 | AX11: ='Notas del Moodle'!AG12 -> 2,5 | AZ11: ='Notas del Moodle'!AH12 -> 2,38 | BA11: ='Notas del Moodle'!AI12 -> 7 | BC11: ='Notas del Moodle'!AJ12 -> 2,33 | BE11: ='Notas del Moodle'!AK12 -> 1,87 | BF11: ='Notas del Moodle'!AL12 -> 8 | BH11: ='Notas del Moodle'!AM12 -> 0,4 | BI11: ='Notas del Moodle'!AN12 -> 5,25 | BK11: ='Notas del Moodle'!AO12 -> 2,4 | BM11: ='Notas del Moodle'!AP12 -> 0,38 | BN11: ='Notas del Moodle'!AQ12 -> 6,59 | BO11: ='Notas del Moodle'!AR12 -> - | BP11: ='Notas del Moodle'!AS12 -> 10 | BQ11: ='Notas del Moodle'!AT12 -> - | BR11: ='Notas del Moodle'!AU12 -> 9,59 | BT11: ='Notas del Moodle'!AW12 -> 2 | BV11: ='Notas del Moodle'!AX12 -> 4 | BX11: ='Notas del Moodle'!AY12 -> 4 | BZ11: ='Notas del Moodle'!AZ12 -> 6 | CA11: ='Notas del Moodle'!BA12 -> 5 | CC11: ='Notas del Moodle'!BB12 -> 5 | CE11: ='Notas del Moodle'!BC12 -> 4 | CF11: ='Notas del Moodle'!BD12 -> 7 | CG11: ='Notas del Moodle'!BE12 -> - | CH11: ='Notas del Moodle'!BF12 -> 10 | CI11: ='Notas del Moodle'!BG12 -> - | CJ11: ='Notas del Moodle'!BH12 -> 10 | CL11: ='Notas del Moodle'!BJ12 -> 6 | CN11: ='Notas del Moodle'!BK12 -> 2,79 | CP11: ='Notas del Moodle'!BL12 -> 4,4 | CQ11: ='Notas del Moodle'!BM12 -> 5 | CS11: ='Notas del Moodle'!BN12 -> 2,5 | CT11: ='Notas del Moodle'!BO12 -> 4,83 | CU11: ='Notas del Moodle'!BP12 -> - | CV11: ='Notas del Moodle'!BQ12 -> 10 | CW11: - | CX11: ='Notas del Moodle'!BS12 -> 7,83
A12: 6 | B12: SALOMÉ | C12: CRUZ TRUJILLO | D12: ='Notas del Moodle'!C13 -> 10 | F12: ='Notas del Moodle'!D13 -> 1,2 | G12: ='Notas del Moodle'!E13 -> 7,5 | I12: ='Notas del Moodle'!F13 -> 0,98 | J12: ='Notas del Moodle'!G13 -> 2,7 | L12: ='Notas del Moodle'!H13 -> 6,5 | N12: ='Notas del Moodle'!I13 -> 1,38 | O12: ='Notas del Moodle'!J13 -> 8 | Q12: ='Notas del Moodle'!K13 -> 1 | S12: ='Notas del Moodle'!L13 -> 1,35 | T12: ='Notas del Moodle'!M13 -> 1 | V12: ='Notas del Moodle'!N13 -> 9 | X12: ='Notas del Moodle'!O14 -> 1,74 | Y12: ='Notas del Moodle'!P13 -> 10 | AA12: ='Notas del Moodle'!Q13 -> 2,5 | AB12: ='Notas del Moodle'!R13 -> 6,59 | AC12: ='Notas del Moodle'!S13 -> - | AD12: ='Notas del Moodle'!T13 -> 10 | AE12: ='Notas del Moodle'!U13 -> - | AF12: ='Notas del Moodle'!V13 -> 9,59 | AH12: ='Notas del Moodle'!X13 -> 10 | AJ12: ='Notas del Moodle'!Y13 -> 1 | AK12: ='Notas del Moodle'!Z13 -> 1 | AM12: ='Notas del Moodle'!AA13 -> 3,25 | AO12: ='Notas del Moodle'!AB13 -> 2,4 | AQ12: ='Notas del Moodle'!AC13 -> 0,9 | AS12: ='Notas del Moodle'!AD13 -> 2,64 | AT12: ='Notas del Moodle'!AE13 -> 3 | AV12: ='Notas del Moodle'!AF13 -> 3,85 | AX12: ='Notas del Moodle'!AG13 -> 2,5 | AZ12: ='Notas del Moodle'!AH13 -> 2,34 | BA12: ='Notas del Moodle'!AI13 -> 7 | BC12: ='Notas del Moodle'!AJ13 -> 2,67 | BE12: ='Notas del Moodle'!AK13 -> 1,93 | BF12: ='Notas del Moodle'!AL13 -> 6 | BH12: ='Notas del Moodle'!AM13 -> 0,3 | BI12: ='Notas del Moodle'!AN13 -> 6 | BK12: ='Notas del Moodle'!AO13 -> 2,8 | BM12: ='Notas del Moodle'!AP13 -> 0,44 | BN12: ='Notas del Moodle'!AQ13 -> 6,06 | BO12: ='Notas del Moodle'!AR13 -> - | BP12: ='Notas del Moodle'!AS13 -> 10 | BQ12: ='Notas del Moodle'!AT13 -> - | BR12: ='Notas del Moodle'!AU13 -> 9,06 | BT12: ='Notas del Moodle'!AW13 -> 2 | BV12: ='Notas del Moodle'!AX13 -> 4 | BX12: ='Notas del Moodle'!AY13 -> 4 | BZ12: ='Notas del Moodle'!AZ13 -> 6 | CA12: ='Notas del Moodle'!BA13 -> 4,25 | CC12: ='Notas del Moodle'!BB13 -> 5 | CE12: ='Notas del Moodle'!BC13 -> 3,7 | CF12: ='Notas del Moodle'!BD13 -> 6,79 | CG12: ='Notas del Moodle'!BE13 -> - | CH12: ='Notas del Moodle'!BF13 -> 10 | CI12: ='Notas del Moodle'!BG13 -> - | CJ12: ='Notas del Moodle'!BH13 -> 9,79 | CL12: ='Notas del Moodle'!BJ13 -> 7 | CN12: ='Notas del Moodle'!BK13 -> 3 | CP12: ='Notas del Moodle'!BL13 -> 5 | CQ12: ='Notas del Moodle'!BM13 -> 8,25 | CS12: ='Notas del Moodle'!BN13 -> 4,13 | CT12: ='Notas del Moodle'!BO13 -> 6,39 | CU12: ='Notas del Moodle'!BP13 -> - | CV12: ='Notas del Moodle'!BQ13 -> 10 | CW12: - | CX12: ='Notas del Moodle'!BS13 -> 9,39
A13: 7 | B13: Alejandro | C13: De Lera Saenz De Miera | D13: ='Notas del Moodle'!C14 -> 10 | F13: ='Notas del Moodle'!D14 -> 1,2 | G13: ='Notas del Moodle'!E14 -> 7,5 | I13: ='Notas del Moodle'!F14 -> 0,98 | J13: ='Notas del Moodle'!G14 -> 2,7 | L13: ='Notas del Moodle'!H14 -> 5,5 | N13: ='Notas del Moodle'!I14 -> 1,23 | O13: ='Notas del Moodle'!J14 -> 6 | Q13: ='Notas del Moodle'!K14 -> 0,7 | S13: ='Notas del Moodle'!L14 -> 1,01 | T13: ='Notas del Moodle'!M14 -> 0,7 | V13: ='Notas del Moodle'!N14 -> 8 | X13: ='Notas del Moodle'!O15 -> 1,96 | Y13: ='Notas del Moodle'!P14 -> 10 | AA13: ='Notas del Moodle'!Q14 -> 2,5 | AB13: ='Notas del Moodle'!R14 -> 6,06 | AC13: ='Notas del Moodle'!S14 -> - | AD13: ='Notas del Moodle'!T14 -> 8,5 | AE13: ='Notas del Moodle'!U14 -> - | AF13: ='Notas del Moodle'!V14 -> 8,61 | AH13: ='Notas del Moodle'!X14 -> 7,5 | AJ13: ='Notas del Moodle'!Y14 -> 0,75 | AK13: ='Notas del Moodle'!Z14 -> 1 | AM13: ='Notas del Moodle'!AA14 -> 4,25 | AO13: ='Notas del Moodle'!AB14 -> 3 | AQ13: ='Notas del Moodle'!AC14 -> 0,8 | AS13: ='Notas del Moodle'!AD14 -> 3,17 | AT13: ='Notas del Moodle'!AE14 -> 2 | AV13: ='Notas del Moodle'!AF14 -> 2 | AX13: ='Notas del Moodle'!AG14 -> 2,25 | AZ13: ='Notas del Moodle'!AH14 -> 1,56 | BA13: ='Notas del Moodle'!AI14 -> 7 | BC13: ='Notas del Moodle'!AJ14 -> 2 | BE13: ='Notas del Moodle'!AK14 -> 1,8 | BF13: ='Notas del Moodle'!AL14 -> 7 | BH13: ='Notas del Moodle'!AM14 -> 0,35 | BI13: ='Notas del Moodle'!AN14 -> 6 | BK13: ='Notas del Moodle'!AO14 -> 1,2 | BM13: ='Notas del Moodle'!AP14 -> 0,36 | BN13: ='Notas del Moodle'!AQ14 -> 5,59 | BO13: ='Notas del Moodle'!AR14 -> - | BP13: ='Notas del Moodle'!AS14 -> 8 | BQ13: ='Notas del Moodle'!AT14 -> - | BR13: ='Notas del Moodle'!AU14 -> 7,99 | BT13: ='Notas del Moodle'!AW14 -> 2 | BV13: ='Notas del Moodle'!AX14 -> 2,75 | BX13: ='Notas del Moodle'!AY14 -> 3,8 | BZ13: ='Notas del Moodle'!AZ14 -> 5,13 | CA13: ='Notas del Moodle'!BA14 -> 5 | CC13: ='Notas del Moodle'!BB14 -> 4,5 | CE13: ='Notas del Moodle'!BC14 -> 3,8 | CF13: ='Notas del Moodle'!BD14 -> 6,25 | CG13: ='Notas del Moodle'!BE14 -> - | CH13: ='Notas del Moodle'!BF14 -> 7 | CI13: ='Notas del Moodle'!BG14 -> - | CJ13: ='Notas del Moodle'!BH14 -> 8,35 | CL13: ='Notas del Moodle'!BJ14 -> 4 | CN13: ='Notas del Moodle'!BK14 -> 2,57 | CP13: ='Notas del Moodle'!BL14 -> 3,29 | CQ13: ='Notas del Moodle'!BM14 -> 7,25 | CS13: ='Notas del Moodle'!BN14 -> 3,63 | CT13: ='Notas del Moodle'!BO14 -> 4,84 | CU13: ='Notas del Moodle'!BP14 -> - | CV13: ='Notas del Moodle'!BQ14 -> 8 | CW13: - | CX13: ='Notas del Moodle'!BS14 -> 7,24
A14: 8 | B14: JESUS | C14: FERNANDEZ FERNANDEZ | D14: ='Notas del Moodle'!C15 -> 8,5 | F14: ='Notas del Moodle'!D15 -> 1,02 | G14: ='Notas del Moodle'!E15 -> 6 | I14: ='Notas del Moodle'!F15 -> 0,78 | J14: ='Notas del Moodle'!G15 -> 2,1 | L14: ='Notas del Moodle'!H15 -> 4,5 | N14: ='Notas del Moodle'!I15 -> 0,99 | O14: ='Notas del Moodle'!J15 -> 5,5 | Q14: ='Notas del Moodle'!K15 -> 0,7 | S14: ='Notas del Moodle'!L15 -> 0,93 | T14: ='Notas del Moodle'!M15 -> 0,8 | V14: ='Notas del Moodle'!N15 -> 9 | X14: ='Notas del Moodle'!O16 -> 1,96 | Y14: ='Notas del Moodle'!P15 -> 9,5 | AA14: ='Notas del Moodle'!Q15 -> 2,38 | AB14: ='Notas del Moodle'!R15 -> 5,64 | AC14: ='Notas del Moodle'!S15 -> - | AD14: ='Notas del Moodle'!T15 -> 8 | AE14: ='Notas del Moodle'!U15 -> - | AF14: ='Notas del Moodle'!V15 -> 8,04 | AH14: ='Notas del Moodle'!X15 -> 8 | AJ14: ='Notas del Moodle'!Y15 -> 0,8 | AK14: ='Notas del Moodle'!Z15 -> 0 | AM14: ='Notas del Moodle'!AA15 -> 3,5 | AO14: ='Notas del Moodle'!AB15 -> 3 | AQ14: ='Notas del Moodle'!AC15 -> 0,8 | AS14: ='Notas del Moodle'!AD15 -> 2,56 | AT14: ='Notas del Moodle'!AE15 -> 1 | AV14: ='Notas del Moodle'!AF15 -> 2,25 | AX14: ='Notas del Moodle'!AG15 -> 2,25 | AZ14: ='Notas del Moodle'!AH15 -> 1,38 | BA14: ='Notas del Moodle'!AI15 -> 3,5 | BC14: ='Notas del Moodle'!AJ15 -> 1,33 | BE14: ='Notas del Moodle'!AK15 -> 0,97 | BF14: ='Notas del Moodle'!AL15 -> 8 | BH14: ='Notas del Moodle'!AM15 -> 0,4 | BI14: ='Notas del Moodle'!AN15 -> 5 | BK14: ='Notas del Moodle'!AO15 -> 1,6 | BM14: ='Notas del Moodle'!AP15 -> 0,33 | BN14: ='Notas del Moodle'!AQ15 -> 4,51 | BO14: ='Notas del Moodle'!AR15 -> - | BP14: ='Notas del Moodle'!AS15 -> 7 | BQ14: ='Notas del Moodle'!AT15 -> - | BR14: ='Notas del Moodle'!AU15 -> 6,61 | BT14: ='Notas del Moodle'!AW15 -> 2 | BV14: ='Notas del Moodle'!AX15 -> 4 | BX14: ='Notas del Moodle'!AY15 -> 3,4 | BZ14: ='Notas del Moodle'!AZ15 -> 5,64 | CA14: ='Notas del Moodle'!BA15 -> 5 | CC14: ='Notas del Moodle'!BB15 -> 4,33 | CE14: ='Notas del Moodle'!BC15 -> 3,73 | CF14: ='Notas del Moodle'!BD15 -> 6,56 | CG14: ='Notas del Moodle'!BE15 -> - | CH14: ='Notas del Moodle'!BF15 -> 9,5 | CI14: ='Notas del Moodle'!BG15 -> - | CJ14: ='Notas del Moodle'!BH15 -> 9,41 | CL14: ='Notas del Moodle'!BJ15 -> 5 | CN14: ='Notas del Moodle'!BK15 -> 2,14 | CP14: ='Notas del Moodle'!BL15 -> 3,57 | CQ14: ='Notas del Moodle'!BM15 -> 1,75 | CS14: ='Notas del Moodle'!BN15 -> 0,88 | CT14: ='Notas del Moodle'!BO15 -> 3,12 | CU14: ='Notas del Moodle'!BP15 -> - | CV14: ='Notas del Moodle'!BQ15 -> 6 | CW14: - | CX14: ='Notas del Moodle'!BS15 -> 4,92
A15: 9 | B15: Lucía | C15: Guerrero Mouriz | D15: ='Notas del Moodle'!C16 -> 10 | F15: ='Notas del Moodle'!D16 -> 1,2 | G15: ='Notas del Moodle'!E16 -> 9,5 | I15: ='Notas del Moodle'!F16 -> 1,24 | J15: ='Notas del Moodle'!G16 -> 2,1 | L15: ='Notas del Moodle'!H16 -> 7 | N15: ='Notas del Moodle'!I16 -> 1,37 | O15: ='Notas del Moodle'!J16 -> 8 | Q15: ='Notas del Moodle'!K16 -> 0,9 | S15: ='Notas del Moodle'!L16 -> 1,34 | T15: ='Notas del Moodle'!M16 -> 0,8 | V15: ='Notas del Moodle'!N16 -> 9 | X15: ='Notas del Moodle'!O17 -> 1,94 | Y15: ='Notas del Moodle'!P16 -> 10 | AA15: ='Notas del Moodle'!Q16 -> 2,5 | AB15: ='Notas del Moodle'!R16 -> 6,73 | AC15: ='Notas del Moodle'!S16 -> - | AD15: ='Notas del Moodle'!T16 -> 8 | AE15: ='Notas del Moodle'!U16 -> - | AF15: ='Notas del Moodle'!V16 -> 9,13 | AH15: ='Notas del Moodle'!X16 -> 8,5 | AJ15: ='Notas del Moodle'!Y16 -> 0,85 | AK15: ='Notas del Moodle'!Z16 -> 1 | AM15: ='Notas del Moodle'!AA16 -> 1,25 | AO15: ='Notas del Moodle'!AB16 -> 1,7 | AQ15: ='Notas del Moodle'!AC16 -> 1 | AS15: ='Notas del Moodle'!AD16 -> 1,73 | AT15: ='Notas del Moodle'!AE16 -> 3 | AV15: ='Notas del Moodle'!AF16 -> 4 | AX15: ='Notas del Moodle'!AG16 -> 1,75 | AZ15: ='Notas del Moodle'!AH16 -> 2,19 | BA15: ='Notas del Moodle'!AI16 -> 7 | BC15: ='Notas del Moodle'!AJ16 -> 2,67 | BE15: ='Notas del Moodle'!AK16 -> 1,93 | BF15: ='Notas del Moodle'!AL16 -> 8,5 | BH15: ='Notas del Moodle'!AM16 -> 0,43 | BI15: ='Notas del Moodle'!AN16 -> 6 | BK15: ='Notas del Moodle'!AO16 -> 2,4 | BM15: ='Notas del Moodle'!AP16 -> 0,42 | BN15: ='Notas del Moodle'!AQ16 -> 5,29 | BO15: ='Notas del Moodle'!AR16 -> - | BP15: ='Notas del Moodle'!AS16 -> 9 | BQ15: ='Notas del Moodle'!AT16 -> - | BR15: ='Notas del Moodle'!AU16 -> 7,99 | BT15: ='Notas del Moodle'!AW16 -> 2 | BV15: ='Notas del Moodle'!AX16 -> 2,25 | BX15: ='Notas del Moodle'!AY16 -> 3,6 | BZ15: ='Notas del Moodle'!AZ16 -> 4,71 | CA15: ='Notas del Moodle'!BA16 -> 4,25 | CC15: ='Notas del Moodle'!BB16 -> 4,83 | CE15: ='Notas del Moodle'!BC16 -> 3,63 | CF15: ='Notas del Moodle'!BD16 -> 5,84 | CG15: ='Notas del Moodle'!BE16 -> - | CH15: ='Notas del Moodle'!BF16 -> 10 | CI15: ='Notas del Moodle'!BG16 -> - | CJ15: ='Notas del Moodle'!BH16 -> 8,84 | CL15: ='Notas del Moodle'!BJ16 -> 6 | CN15: ='Notas del Moodle'!BK16 -> 2,79 | CP15: ='Notas del Moodle'!BL16 -> 4,4 | CQ15: ='Notas del Moodle'!BM16 -> 10 | CS15: ='Notas del Moodle'!BN16 -> 5 | CT15: ='Notas del Moodle'!BO16 -> 6,58 | CU15: ='Notas del Moodle'!BP16 -> - | CV15: ='Notas del Moodle'!BQ16 -> 7 | CW15: - | CX15: ='Notas del Moodle'!BS16 -> 8,68
A16: 10 | B16: Roque | C16: Mazoy Cortiñas | D16: ='Notas del Moodle'!C17 -> 9 | F16: ='Notas del Moodle'!D17 -> 1,08 | G16: ='Notas del Moodle'!E17 -> 6 | I16: ='Notas del Moodle'!F17 -> 0,78 | J16: ='Notas del Moodle'!G17 -> 2,7 | L16: ='Notas del Moodle'!H17 -> 6,5 | N16: ='Notas del Moodle'!I17 -> 1,38 | O16: ='Notas del Moodle'!J17 -> 9 | Q16: ='Notas del Moodle'!K17 -> 0,6 | S16: ='Notas del Moodle'!L17 -> 1,44 | T16: ='Notas del Moodle'!M17 -> 0,7 | V16: ='Notas del Moodle'!N17 -> 9 | X16: ='Notas del Moodle'!O18 -> 1,96 | Y16: ='Notas del Moodle'!P17 -> 10 | AA16: ='Notas del Moodle'!Q17 -> 2,5 | AB16: ='Notas del Moodle'!R17 -> 6,38 | AC16: ='Notas del Moodle'!S17 -> - | AD16: ='Notas del Moodle'!T17 -> 7 | AE16: ='Notas del Moodle'!U17 -> - | AF16: ='Notas del Moodle'!V17 -> 8,48 | AH16: ='Notas del Moodle'!X17 -> 10 | AJ16: ='Notas del Moodle'!Y17 -> 1 | AK16: ='Notas del Moodle'!Z17 -> 1 | AM16: ='Notas del Moodle'!AA17 -> 2,5 | AO16: ='Notas del Moodle'!AB17 -> 0,2 | AQ16: ='Notas del Moodle'!AC17 -> 0,7 | AS16: ='Notas del Moodle'!AD17 -> 1,54 | AT16: ='Notas del Moodle'!AE17 -> 2 | AV16: ='Notas del Moodle'!AF17 -> 4 | AX16: ='Notas del Moodle'!AG17 -> 1,5 | AZ16: ='Notas del Moodle'!AH17 -> 1,88 | BA16: ='Notas del Moodle'!AI17 -> 7 | BC16: ='Notas del Moodle'!AJ17 -> 1,67 | BE16: ='Notas del Moodle'!AK17 -> 1,73 | BF16: ='Notas del Moodle'!AL17 -> 9,5 | BH16: ='Notas del Moodle'!AM17 -> 0,48 | BI16: ='Notas del Moodle'!AN17 -> 5,5 | BK16: ='Notas del Moodle'!AO17 -> 1,2 | BM16: ='Notas del Moodle'!AP17 -> 0,34 | BN16: ='Notas del Moodle'!AQ17 -> 4,88 | BO16: ='Notas del Moodle'!AR17 -> - | BP16: ='Notas del Moodle'!AS17 -> 4 | BQ16: ='Notas del Moodle'!AT17 -> - | BR16: ='Notas del Moodle'!AU17 -> 4 | BT16: ='Notas del Moodle'!AW17 -> 1 | BV16: ='Notas del Moodle'!AX17 -> 3,5 | BX16: ='Notas del Moodle'!AY17 -> 3,6 | BZ16: ='Notas del Moodle'!AZ17 -> 4,86 | CA16: ='Notas del Moodle'!BA17 -> 4,25 | CC16: ='Notas del Moodle'!BB17 -> 5 | CE16: ='Notas del Moodle'!BC17 -> 3,7 | CF16: ='Notas del Moodle'!BD17 -> 5,99 | CG16: ='Notas del Moodle'!BE17 -> - | CH16: ='Notas del Moodle'!BF17 -> 7,5 | CI16: ='Notas del Moodle'!BG17 -> - | CJ16: ='Notas del Moodle'!BH17 -> 8,24 | CL16: ='Notas del Moodle'!BJ17 -> 4 | CN16: ='Notas del Moodle'!BK17 -> 2,57 | CP16: ='Notas del Moodle'!BL17 -> 3,29 | CQ16: ='Notas del Moodle'!BM17 -> 3,75 | CS16: ='Notas del Moodle'!BN17 -> 1,88 | CT16: ='Notas del Moodle'!BO17 -> 3,62 | CU16: ='Notas del Moodle'!BP17 -> - | CV16: ='Notas del Moodle'!BQ17 -> 6 | CW16: - | CX16: ='Notas del Moodle'!BS17 -> 5,42
A17: 11 | B17: GUILLERMO | C17: MORENO MATA | D17: ='Notas del Moodle'!C18 -> 10 | F17: ='Notas del Moodle'!D18 -> 1,2 | G17: ='Notas del Moodle'!E18 -> 4 | I17: ='Notas del Moodle'!F18 -> 0,52 | J17: ='Notas del Moodle'!G18 -> 2,4 | L17: ='Notas del Moodle'!H18 -> 7 | N17: ='Notas del Moodle'!I18 -> 1,41 | O17: ='Notas del Moodle'!J18 -> 8,25 | Q17: ='Notas del Moodle'!K18 -> 0,8 | S17: ='Notas del Moodle'!L18 -> 1,36 | T17: ='Notas del Moodle'!M18 -> 0,8 | V17: ='Notas del Moodle'!N18 -> 9 | X17: ='Notas del Moodle'!O19 -> 2 | Y17: ='Notas del Moodle'!P18 -> 8,75 | AA17: ='Notas del Moodle'!Q18 -> 2,19 | AB17: ='Notas del Moodle'!R18 -> 6,05 | AC17: ='Notas del Moodle'!S18 -> - | AD17: ='Notas del Moodle'!T18 -> 9 | AE17: ='Notas del Moodle'!U18 -> - | AF17: ='Notas del Moodle'!V18 -> 8,75 | AH17: ='Notas del Moodle'!X18 -> 9,5 | AJ17: ='Notas del Moodle'!Y18 -> 0,95 | AK17: ='Notas del Moodle'!Z18 -> 1 | AM17: ='Notas del Moodle'!AA18 -> 4,25 | AO17: ='Notas del Moodle'!AB18 -> 3 | AQ17: ='Notas del Moodle'!AC18 -> 0,7 | AS17: ='Notas del Moodle'!AD18 -> 3,13 | AT17: ='Notas del Moodle'!AE18 -> 3 | AV17: ='Notas del Moodle'!AF18 -> 2,25 | AX17: ='Notas del Moodle'!AG18 -> 2,25 | AZ17: ='Notas del Moodle'!AH18 -> 1,88 | BA17: ='Notas del Moodle'!AI18 -> 7 | BC17: ='Notas del Moodle'!AJ18 -> 2,33 | BE17: ='Notas del Moodle'!AK18 -> 1,87 | BF17: ='Notas del Moodle'!AL18 -> 6,5 | BH17: ='Notas del Moodle'!AM18 -> 0,33 | BI17: ='Notas del Moodle'!AN18 -> 6 | BK17: ='Notas del Moodle'!AO18 -> 2,4 | BM17: ='Notas del Moodle'!AP18 -> 0,42 | BN17: ='Notas del Moodle'!AQ18 -> 6,01 | BO17: ='Notas del Moodle'!AR18 -> - | BP17: ='Notas del Moodle'!AS18 -> 9 | BQ17: ='Notas del Moodle'!AT18 -> - | BR17: ='Notas del Moodle'!AU18 -> 8,71 | BT17: ='Notas del Moodle'!AW18 -> 2 | BV17: ='Notas del Moodle'!AX18 -> 4 | BX17: ='Notas del Moodle'!AY18 -> 3,8 | BZ17: ='Notas del Moodle'!AZ18 -> 5,88 | CA17: ='Notas del Moodle'!BA18 -> 5 | CC17: ='Notas del Moodle'!BB18 -> 4,33 | CE17: ='Notas del Moodle'!BC18 -> 3,73 | CF17: ='Notas del Moodle'!BD18 -> 6,73 | CG17: ='Notas del Moodle'!BE18 -> - | CH17: ='Notas del Moodle'!BF18 -> 9 | CI17: ='Notas del Moodle'!BG18 -> - | CJ17: ='Notas del Moodle'!BH18 -> 9,43 | CL17: ='Notas del Moodle'!BJ18 -> 5 | CN17: ='Notas del Moodle'!BK18 -> 2,36 | CP17: ='Notas del Moodle'!BL18 -> 3,68 | CQ17: ='Notas del Moodle'!BM18 -> 6,75 | CS17: ='Notas del Moodle'!BN18 -> 3,38 | CT17: ='Notas del Moodle'!BO18 -> 4,94 | CU17: ='Notas del Moodle'!BP18 -> - | CV17: ='Notas del Moodle'!BQ18 -> 8 | CW17: - | CX17: ='Notas del Moodle'!BS18 -> 7,34
A18: 12 | B18: LAURA | C18: PANIAGUA ARIAS | D18: ='Notas del Moodle'!C19 -> 10 | F18: ='Notas del Moodle'!D19 -> 1,2 | G18: ='Notas del Moodle'!E19 -> 9,5 | I18: ='Notas del Moodle'!F19 -> 1,24 | J18: ='Notas del Moodle'!G19 -> 3 | L18: ='Notas del Moodle'!H19 -> 6,5 | N18: ='Notas del Moodle'!I19 -> 1,43 | O18: ='Notas del Moodle'!J19 -> 7 | Q18: ='Notas del Moodle'!K19 -> 1 | S18: ='Notas del Moodle'!L19 -> 1,2 | T18: ='Notas del Moodle'!M19 -> 1 | V18: ='Notas del Moodle'!N19 -> 9 | X18: ='Notas del Moodle'!O20 -> 1,98 | Y18: ='Notas del Moodle'!P19 -> 9 | AA18: ='Notas del Moodle'!Q19 -> 2,25 | AB18: ='Notas del Moodle'!R19 -> 6,52 | AC18: ='Notas del Moodle'!S19 -> - | AD18: ='Notas del Moodle'!T19 -> 10 | AE18: ='Notas del Moodle'!U19 -> - | AF18: ='Notas del Moodle'!V19 -> 9,52 | AH18: ='Notas del Moodle'!X19 -> 10 | AJ18: ='Notas del Moodle'!Y19 -> 1 | AK18: ='Notas del Moodle'!Z19 -> 1 | AM18: ='Notas del Moodle'!AA19 -> 4,5 | AO18: ='Notas del Moodle'!AB19 -> 3 | AQ18: ='Notas del Moodle'!AC19 -> 1 | AS18: ='Notas del Moodle'!AD19 -> 3,33 | AT18: ='Notas del Moodle'!AE19 -> 3 | AV18: ='Notas del Moodle'!AF19 -> 4 | AX18: ='Notas del Moodle'!AG19 -> 1,75 | AZ18: ='Notas del Moodle'!AH19 -> 2,19 | BA18: ='Notas del Moodle'!AI19 -> 7 | BC18: ='Notas del Moodle'!AJ19 -> 2,33 | BE18: ='Notas del Moodle'!AK19 -> 1,87 | BF18: ='Notas del Moodle'!AL19 -> 7,5 | BH18: ='Notas del Moodle'!AM19 -> 0,38 | BI18: ='Notas del Moodle'!AN19 -> 6 | BK18: ='Notas del Moodle'!AO19 -> 4 | BM18: ='Notas del Moodle'!AP19 -> 0,5 | BN18: ='Notas del Moodle'!AQ19 -> 6,49 | BO18: ='Notas del Moodle'!AR19 -> - | BP18: ='Notas del Moodle'!AS19 -> 10 | BQ18: ='Notas del Moodle'!AT19 -> - | BR18: ='Notas del Moodle'!AU19 -> 9,49 | BT18: ='Notas del Moodle'!AW19 -> 2 | BV18: ='Notas del Moodle'!AX19 -> 4 | BX18: ='Notas del Moodle'!AY19 -> 3,8 | BZ18: ='Notas del Moodle'!AZ19 -> 5,88 | CA18: ='Notas del Moodle'!BA19 -> 5 | CC18: ='Notas del Moodle'!BB19 -> 4,83 | CE18: ='Notas del Moodle'!BC19 -> 3,93 | CF18: ='Notas del Moodle'!BD19 -> 6,87 | CG18: ='Notas del Moodle'!BE19 -> - | CH18: ='Notas del Moodle'!BF19 -> 10 | CI18: ='Notas del Moodle'!BG19 -> - | CJ18: ='Notas del Moodle'!BH19 -> 9,87 | CL18: ='Notas del Moodle'!BJ19 -> 6 | CN18: ='Notas del Moodle'!BK19 -> 2,57 | CP18: ='Notas del Moodle'!BL19 -> 4,29 | CQ18: ='Notas del Moodle'!BM19 -> 9,5 | CS18: ='Notas del Moodle'!BN19 -> 4,75 | CT18: ='Notas del Moodle'!BO19 -> 6,33 | CU18: ='Notas del Moodle'!BP19 -> - | CV18: ='Notas del Moodle'!BQ19 -> 10 | CW18: - | CX18: ='Notas del Moodle'!BS19 -> 9,33
A19: 13 | B19: María del Rosario | C19: Quintáns Carballo | D19: ='Notas del Moodle'!C20 -> 10 | F19: ='Notas del Moodle'!D20 -> 1,2 | G19: ='Notas del Moodle'!E20 -> 7 | I19: ='Notas del Moodle'!F20 -> 0,91 | J19: ='Notas del Moodle'!G20 -> 3 | L19: ='Notas del Moodle'!H20 -> 7 | N19: ='Notas del Moodle'!I20 -> 1,5 | O19: ='Notas del Moodle'!J20 -> 9 | Q19: ='Notas del Moodle'!K20 -> 1 | S19: ='Notas del Moodle'!L20 -> 1,5 | T19: ='Notas del Moodle'!M20 -> 0,9 | V19: ='Notas del Moodle'!N20 -> 9 | X19: ='Notas del Moodle'!O21 -> 1,98 | Y19: ='Notas del Moodle'!P20 -> 10 | AA19: ='Notas del Moodle'!Q20 -> 2,5 | AB19: ='Notas del Moodle'!R20 -> 6,71 | AC19: ='Notas del Moodle'!S20 -> - | AD19: ='Notas del Moodle'!T20 -> 10 | AE19: ='Notas del Moodle'!U20 -> - | AF19: ='Notas del Moodle'!V20 -> 9,71 | AH19: ='Notas del Moodle'!X20 -> - | AJ19: ='Notas del Moodle'!Y20 -> - | AK19: ='Notas del Moodle'!Z20 -> - | AM19: ='Notas del Moodle'!AA20 -> - | AO19: ='Notas del Moodle'!AB20 -> - | AQ19: ='Notas del Moodle'!AC20 -> - | AS19: ='Notas del Moodle'!AD20 -> - | AT19: ='Notas del Moodle'!AE20 -> - | AV19: ='Notas del Moodle'!AF20 -> - | AX19: ='Notas del Moodle'!AG20 -> - | AZ19: ='Notas del Moodle'!AH20 -> - | BA19: ='Notas del Moodle'!AI20 -> - | BC19: ='Notas del Moodle'!AJ20 -> - | BE19: ='Notas del Moodle'!AK20 -> - | BF19: ='Notas del Moodle'!AL20 -> - | BH19: ='Notas del Moodle'!AM20 -> - | BI19: ='Notas del Moodle'!AN20 -> - | BK19: ='Notas del Moodle'!AO20 -> - | BM19: ='Notas del Moodle'!AP20 -> - | BN19: ='Notas del Moodle'!AQ20 -> 0 | BO19: ='Notas del Moodle'!AR20 -> - | BP19: ='Notas del Moodle'!AS20 -> - | BQ19: ='Notas del Moodle'!AT20 -> - | BR19: CV | BS19: ='Notas del Moodle'!AV20 -> CV | BT19: ='Notas del Moodle'!AW20 -> 2 | BV19: ='Notas del Moodle'!AX20 -> 3,5 | BX19: ='Notas del Moodle'!AY20 -> 3,6 | BZ19: ='Notas del Moodle'!AZ20 -> 5,46 | CA19: ='Notas del Moodle'!BA20 -> 5 | CC19: ='Notas del Moodle'!BB20 -> 4,83 | CE19: ='Notas del Moodle'!BC20 -> 3,93 | CF19: ='Notas del Moodle'!BD20 -> 6,57 | CG19: ='Notas del Moodle'!BE20 -> - | CH19: ='Notas del Moodle'!BF20 -> 10 | CI19: ='Notas del Moodle'!BG20 -> - | CJ19: ='Notas del Moodle'!BH20 -> 9,57 | CL19: ='Notas del Moodle'!BJ20 -> 6 | CN19: ='Notas del Moodle'!BK20 -> 2,36 | CP19: ='Notas del Moodle'!BL20 -> 4,18 | CQ19: ='Notas del Moodle'!BM20 -> 8,75 | CS19: ='Notas del Moodle'!BN20 -> 4,38 | CT19: ='Notas del Moodle'!BO20 -> 5,99 | CU19: ='Notas del Moodle'!BP20 -> - | CV19: ='Notas del Moodle'!BQ20 -> 10 | CW19: - | CX19: ='Notas del Moodle'!BS20 -> 8,99
A20: 14 | B20: ALAIN | C20: TALLON JIMENEZ | D20: ='Notas del Moodle'!C21 -> 10 | F20: ='Notas del Moodle'!D21 -> 1,2 | G20: ='Notas del Moodle'!E21 -> 7,5 | I20: ='Notas del Moodle'!F21 -> 0,98 | J20: ='Notas del Moodle'!G21 -> 3 | L20: ='Notas del Moodle'!H21 -> 7 | N20: ='Notas del Moodle'!I21 -> 1,5 | O20: ='Notas del Moodle'!J21 -> 9 | Q20: ='Notas del Moodle'!K21 -> 0,9 | S20: ='Notas del Moodle'!L21 -> 1,49 | T20: ='Notas del Moodle'!M21 -> 0,9 | V20: ='Notas del Moodle'!N21 -> 9 | X20: ='Notas del Moodle'!O22 -> 0 | Y20: ='Notas del Moodle'!P21 -> 10 | AA20: ='Notas del Moodle'!Q21 -> 2,5 | AB20: ='Notas del Moodle'!R21 -> 6,76 | AC20: ='Notas del Moodle'!S21 -> - | AD20: ='Notas del Moodle'!T21 -> 10 | AE20: ='Notas del Moodle'!U21 -> - | AF20: ='Notas del Moodle'!V21 -> 9,76 | AH20: ='Notas del Moodle'!X21 -> 9 | AJ20: ='Notas del Moodle'!Y21 -> 0,9 | AK20: ='Notas del Moodle'!Z21 -> 1 | AM20: ='Notas del Moodle'!AA21 -> 4,25 | AO20: ='Notas del Moodle'!AB21 -> 3 | AQ20: ='Notas del Moodle'!AC21 -> 1 | AS20: ='Notas del Moodle'!AD21 -> 3,24 | AT20: ='Notas del Moodle'!AE21 -> 2 | AV20: ='Notas del Moodle'!AF21 -> 4 | AX20: ='Notas del Moodle'!AG21 -> 2,25 | AZ20: ='Notas del Moodle'!AH21 -> 2,06 | BA20: ='Notas del Moodle'!AI21 -> 7 | BC20: ='Notas del Moodle'!AJ21 -> 2,67 | BE20: ='Notas del Moodle'!AK21 -> 1,93 | BF20: ='Notas del Moodle'!AL21 -> 7,5 | BH20: ='Notas del Moodle'!AM21 -> 0,38 | BI20: ='Notas del Moodle'!AN21 -> 6 | BK20: ='Notas del Moodle'!AO21 -> 2,4 | BM20: ='Notas del Moodle'!AP21 -> 0,42 | BN20: ='Notas del Moodle'!AQ21 -> 6,25 | BO20: ='Notas del Moodle'!AR21 -> - | BP20: ='Notas del Moodle'!AS21 -> 8 | BQ20: ='Notas del Moodle'!AT21 -> - | BR20: ='Notas del Moodle'!AU21 -> 8,65 | BT20: ='Notas del Moodle'!AW21 -> 2 | BV20: ='Notas del Moodle'!AX21 -> 2 | BX20: ='Notas del Moodle'!AY21 -> 3,8 | BZ20: ='Notas del Moodle'!AZ21 -> 4,68 | CA20: ='Notas del Moodle'!BA21 -> 5 | CC20: ='Notas del Moodle'!BB21 -> 4 | CE20: ='Notas del Moodle'!BC21 -> 3,6 | CF20: ='Notas del Moodle'!BD21 -> 5,8 | CG20: ='Notas del Moodle'!BE21 -> - | CH20: ='Notas del Moodle'!BF21 -> 10 | CI20: ='Notas del Moodle'!BG21 -> - | CJ20: ='Notas del Moodle'!BH21 -> 8,8 | CL20: ='Notas del Moodle'!BJ21 -> 5 | CN20: ='Notas del Moodle'!BK21 -> 2,57 | CP20: ='Notas del Moodle'!BL21 -> 3,79 | CQ20: ='Notas del Moodle'!BM21 -> 5,25 | CS20: ='Notas del Moodle'!BN21 -> 2,63 | CT20: ='Notas del Moodle'!BO21 -> 4,49 | CU20: ='Notas del Moodle'!BP21 -> - | CV20: ='Notas del Moodle'!BQ21 -> 8,5 | CW20: - | CX20: ='Notas del Moodle'!BS21 -> 7,04
B25: LEYENDA COLORES | E25: LEYENDA DE LOS COLORES DE LAS CASILLAS
B27: AUTOMATICA (MOODLE) | F27: AUTOMÁTICA (MOODLE)
G29: - | J29: TAREA NO ENTREGADA
G31: 0 | J31: ACTIVIDAD CALIFICADA CON UN 0
G32: -
G33: 0 | J33: ACTIVIDAD CALIFICADA EN EL INFORME DE CALIFICACIÓN MANUALMENTE
F36: MANUAL EN EL EXCEL
J38: EXAMEN < 5
J40: NOTA FINAL DEL MÓDULO MODIFICADA MANUALMENTE

Sheet Notas del Moodle
A1: Informe de calificación Curso: CICLO INICIAL KARATE MADRID KA06
A3: 14 Alumnos
C5: MED - C101 BASES DEL COMPORTAMIENTO DEPORTIVO | X5: MED - C102 PRIMEROS AUXILIOS | AW5: MED -C103 ACTIVIDAD FÍSICA ADAPTADA Y DISCAPACIDAD | BJ5: MED - C104 ORGANIZACIÓN DEPORTIVA
C6: TEMA 1. EL DEPORTE, ESCUELA DE VALORES (12%) | E6: TEMA 2. EL TÉCNICO DEPORTIVO COMO LIDER TRANSMISOR DE VALORES (13%) | G6: TEMA 6. UN PASEO POR LA INFANCIA (15%) | J6: TEMA 7. PRÁCTICAS DEPORTIVAS AJUSTADAS A LA INFANCIA (15%) | M6: TEMA 14. MOTIVACIÓN ADAPTADA A JÓVENES DEPORTISTAS (20%) | P6: TEMA 16. TRABAJANDO CON GRUPOS (25%) | R6: Total Evaluación Continua Ord. (70%) | S6: Total Evaluación Continua Extr (70%) | T6: Examen presencial Conv.Ordinaria (30%) | U6: Examen presencial Conv.Extr. (30%) | V6: Nota total Módulo | W6: Convalidado | X6: TEMA 8. SITUACIONES DE URGENCIA EN EL DEPORTE (10%) | Z6: TEMA 9. PRESERVAR LA VIDA (35%) | AE6: TEMA 10. ATENCIÓN AL DEPORTISTA LESIONADO I (25%) | AI6: TEMA 11. ATENCIÓN AL DEPORTISTA LESIONADO II (20%) | AL6: TEMA 12. MANTENER LA CALMA (5%) | AN6: TEMA 13. ACTUAR IN SITU (5%) | AQ6: Total Evaluación Continua Ord. (70%) | AR6: Total Evaluación Continua Extr (70%) | AS6: Examen presencial Conv.Ordinaria (30%) | AT6: Examen presencial Conv.Extr. (30%) | AU6: Nota total Módulo | AV6: Convalidado | AW6: TEMA 5. LAS PERSONAS EN SITUACIÓN DE DISCAPACIDAD (60%) | BA6: TEMA 15. LA COMUNICACIÓN EN LA PRÁCTICA INCLUSIVA (40%) | BD6: Total Evaluación Continua Ord. (70%) | BE6: Total Evaluación Continua Extr (70%) | BF6: Examen presencial Conv.Ordinaria (30%) | BG6: Examen presencial Conv.Extr. (30%) | BH6: Nota total Módulo | BI6: Convalidado | BJ6: TEMA 3. ESTRUCTURA DEL DEPORTE ESPAÑOL (50%) | BM6: TEMA 4. ORGANIZACIÓN DEPORTIVA AUTONÓMICA Y LOCAL (50%) | BO6: Total Evaluación Continua Ord. (70%) | BP6: Total Evaluación Continua Extr (70%) | BQ6: Examen presencial Conv.Ordinaria (30%) | BR6: Examen presencial Conv.Extr. (30%) | BS6: Nota total Módulo | BT6: Convalidado
A7: Nombre | B7: Apellidos | C7: Todo valores(100%) | D7: Total tema | E7: Líderes con valor(100%) | F7: Total tema | G7: ¿Qué sabes de la infancia?(30%) | H7: El Retrato Robot(70%) | I7: Total tema | J7: Desmontando a Richard(90%) | K7: Iniciación deportiva respetuosa y segura(10%) | L7: Total tema | M7: Motivar sin palabras(10%) | N7: De Campeones a Mali(90%) | O7: Total tema | P7: Tarea: Case Study Lealtad Rugby Club(100%) | Q7: Total tema | X7: Análisis del entorno y conducta PAS(100%) | Y7: Total tema | Z7: Foro-acertijo: "Staying alive"(10%) | AA7: Taller de RCP: Autoinstrucción(50%) | AB7: DESA(30%) | AC7: Otras situaciones de riesgo vital(10%) | AD7: Total tema | AE7: Rescates y movilización(30%) | AF7: Atención al lesionado en el primer caso(40%) | AG7: ¿ Qué podrías hacer con estos deportistas?(30%) | AH7: Total tema | AI7: Auténtica mala suerte: Noticias e imprevistos en triatlón(70%) | AJ7: Otras lesiones menores(30%) | AK7: Total tema | AL7: Presta ayuda al choque de hockey(100%) | AM7: Total tema | AN7: Atiende in situ a estos deportistas(60%) | AO7: Atención in situ en el escenario de juego(40%) | AP7: Total tema | AW7: Y tú, ¿Cómo miras?(20%) | AX7: Me pongo en la piel(40%) | AY7: ¿Qué sabes sobre la discapacidad?(40%) | AZ7: Total tema | BA7: Entrenar a una persona con discapacidad(50%) | BB7: Cuestionario: Práctica deportiva en personas con discapacidad.(50%) | BC7: Total tema | BJ7: Competencias de las instituciones(70%) | BK7: Quiz: Estructura del deporte nacional(30%) | BL7: Total tema | BM7: Ayudas al deporte: requisitos y criterios de valoración.(100%) | BN7: Total tema
